[2023-11-21T01:05:49.326+0000] {taskinstance.py:1159} INFO - Dependencies all met for dep_context=non-requeueable deps ti=<TaskInstance: dag_animal_shelter1000_data.retrieve_data scheduled__2023-11-15T00:00:00+00:00 [queued]>
[2023-11-21T01:05:49.470+0000] {taskinstance.py:1159} INFO - Dependencies all met for dep_context=requeueable deps ti=<TaskInstance: dag_animal_shelter1000_data.retrieve_data scheduled__2023-11-15T00:00:00+00:00 [queued]>
[2023-11-21T01:05:49.483+0000] {taskinstance.py:1361} INFO - Starting attempt 1 of 2
[2023-11-21T01:05:49.801+0000] {taskinstance.py:1382} INFO - Executing <Task(PythonOperator): retrieve_data> on 2023-11-15 00:00:00+00:00
[2023-11-21T01:05:50.117+0000] {standard_task_runner.py:57} INFO - Started process 120 to run task
[2023-11-21T01:05:50.186+0000] {standard_task_runner.py:84} INFO - Running: ['***', 'tasks', 'run', 'dag_animal_shelter1000_data', 'retrieve_data', 'scheduled__2023-11-15T00:00:00+00:00', '--job-id', '177', '--raw', '--subdir', 'DAGS_FOLDER/DAG.py', '--cfg-path', '/tmp/tmpsq11qrp_']
[2023-11-21T01:05:50.315+0000] {standard_task_runner.py:85} INFO - Job 177: Subtask retrieve_data
[2023-11-21T01:05:51.691+0000] {task_command.py:416} INFO - Running <TaskInstance: dag_animal_shelter1000_data.retrieve_data scheduled__2023-11-15T00:00:00+00:00 [running]> on host 6814c7d47c6b
[2023-11-21T01:05:53.864+0000] {taskinstance.py:1662} INFO - Exporting env vars: AIRFLOW_CTX_DAG_OWNER='***' AIRFLOW_CTX_DAG_ID='dag_animal_shelter1000_data' AIRFLOW_CTX_TASK_ID='retrieve_data' AIRFLOW_CTX_EXECUTION_DATE='2023-11-15T00:00:00+00:00' AIRFLOW_CTX_TRY_NUMBER='1' AIRFLOW_CTX_DAG_RUN_ID='scheduled__2023-11-15T00:00:00+00:00'
[2023-11-21T01:05:54.181+0000] {taskinstance.py:1937} ERROR - Task failed with exception
Traceback (most recent call last):
  File "/home/airflow/.local/lib/python3.8/site-packages/airflow/operators/python.py", line 192, in execute
    return_value = self.execute_callable()
  File "/home/airflow/.local/lib/python3.8/site-packages/airflow/operators/python.py", line 209, in execute_callable
    return self.python_callable(*self.op_args, **self.op_kwargs)
  File "/opt/airflow/dags/Scripts/etl.py", line 53, in retrieve_data
    s3 = boto3.client(
  File "/home/airflow/.local/lib/python3.8/site-packages/boto3/__init__.py", line 92, in client
    return _get_default_session().client(*args, **kwargs)
  File "/home/airflow/.local/lib/python3.8/site-packages/boto3/__init__.py", line 80, in _get_default_session
    setup_default_session()
  File "/home/airflow/.local/lib/python3.8/site-packages/boto3/__init__.py", line 34, in setup_default_session
    DEFAULT_SESSION = Session(**kwargs)
  File "/home/airflow/.local/lib/python3.8/site-packages/boto3/session.py", line 91, in __init__
    self._register_default_handlers()
  File "/home/airflow/.local/lib/python3.8/site-packages/boto3/session.py", line 485, in _register_default_handlers
    boto3.utils.lazy_call(
AttributeError: module 'boto3' has no attribute 'utils'
[2023-11-21T01:05:54.573+0000] {taskinstance.py:1400} INFO - Marking task as UP_FOR_RETRY. dag_id=dag_animal_shelter1000_data, task_id=retrieve_data, execution_date=20231115T000000, start_date=20231121T010549, end_date=20231121T010554
[2023-11-21T01:05:54.964+0000] {standard_task_runner.py:104} ERROR - Failed to execute job 177 for task retrieve_data (module 'boto3' has no attribute 'utils'; 120)
[2023-11-21T01:05:55.155+0000] {local_task_job_runner.py:228} INFO - Task exited with return code 1
[2023-11-21T01:05:57.119+0000] {taskinstance.py:2778} INFO - 0 downstream tasks scheduled from follow-on schedule check
