[2023-11-21T01:16:19.765+0000] {taskinstance.py:1159} INFO - Dependencies all met for dep_context=non-requeueable deps ti=<TaskInstance: dag_animal_shelter1000_data.transform_data scheduled__2023-11-05T00:00:00+00:00 [queued]>
[2023-11-21T01:16:20.000+0000] {taskinstance.py:1159} INFO - Dependencies all met for dep_context=requeueable deps ti=<TaskInstance: dag_animal_shelter1000_data.transform_data scheduled__2023-11-05T00:00:00+00:00 [queued]>
[2023-11-21T01:16:20.004+0000] {taskinstance.py:1361} INFO - Starting attempt 1 of 2
[2023-11-21T01:16:20.298+0000] {taskinstance.py:1382} INFO - Executing <Task(PythonOperator): transform_data> on 2023-11-05 00:00:00+00:00
[2023-11-21T01:16:20.665+0000] {standard_task_runner.py:57} INFO - Started process 120 to run task
[2023-11-21T01:16:21.481+0000] {standard_task_runner.py:84} INFO - Running: ['***', 'tasks', 'run', 'dag_animal_shelter1000_data', 'transform_data', 'scheduled__2023-11-05T00:00:00+00:00', '--job-id', '200', '--raw', '--subdir', 'DAGS_FOLDER/DAG.py', '--cfg-path', '/tmp/tmp183vt2m2']
[2023-11-21T01:16:21.661+0000] {standard_task_runner.py:85} INFO - Job 200: Subtask transform_data
[2023-11-21T01:16:30.125+0000] {task_command.py:416} INFO - Running <TaskInstance: dag_animal_shelter1000_data.transform_data scheduled__2023-11-05T00:00:00+00:00 [running]> on host 6814c7d47c6b
[2023-11-21T01:16:45.737+0000] {taskinstance.py:1662} INFO - Exporting env vars: AIRFLOW_CTX_DAG_OWNER='***' AIRFLOW_CTX_DAG_ID='dag_animal_shelter1000_data' AIRFLOW_CTX_TASK_ID='transform_data' AIRFLOW_CTX_EXECUTION_DATE='2023-11-05T00:00:00+00:00' AIRFLOW_CTX_TRY_NUMBER='1' AIRFLOW_CTX_DAG_RUN_ID='scheduled__2023-11-05T00:00:00+00:00'
[2023-11-21T01:16:48.376+0000] {taskinstance.py:1937} ERROR - Task failed with exception
Traceback (most recent call last):
  File "/home/airflow/.local/lib/python3.8/site-packages/airflow/operators/python.py", line 192, in execute
    return_value = self.execute_callable()
  File "/home/airflow/.local/lib/python3.8/site-packages/airflow/operators/python.py", line 209, in execute_callable
    return self.python_callable(*self.op_args, **self.op_kwargs)
  File "/opt/airflow/dags/Scripts/etl.py", line 118, in transform_data
    obj = s3.get_object(Bucket=bucket_name, Key=s3_object_name)
  File "/home/airflow/.local/lib/python3.8/site-packages/botocore/client.py", line 535, in _api_call
    return self._make_api_call(operation_name, kwargs)
  File "/home/airflow/.local/lib/python3.8/site-packages/botocore/client.py", line 980, in _make_api_call
    raise error_class(parsed_response, operation_name)
botocore.errorfactory.NoSuchKey: An error occurred (NoSuchKey) when calling the GetObject operation: The specified key does not exist.
[2023-11-21T01:16:48.644+0000] {taskinstance.py:1400} INFO - Marking task as UP_FOR_RETRY. dag_id=dag_animal_shelter1000_data, task_id=transform_data, execution_date=20231105T000000, start_date=20231121T011619, end_date=20231121T011648
[2023-11-21T01:16:48.820+0000] {standard_task_runner.py:104} ERROR - Failed to execute job 200 for task transform_data (An error occurred (NoSuchKey) when calling the GetObject operation: The specified key does not exist.; 120)
[2023-11-21T01:16:48.988+0000] {local_task_job_runner.py:228} INFO - Task exited with return code 1
[2023-11-21T01:16:49.074+0000] {taskinstance.py:2778} INFO - 0 downstream tasks scheduled from follow-on schedule check
