[2023-11-21T00:02:41.811+0000] {taskinstance.py:1159} INFO - Dependencies all met for dep_context=non-requeueable deps ti=<TaskInstance: austin_animal_shelter_dag.retrieve_data manual__2023-11-21T00:02:40.015000+00:00 [queued]>
[2023-11-21T00:02:41.816+0000] {taskinstance.py:1159} INFO - Dependencies all met for dep_context=requeueable deps ti=<TaskInstance: austin_animal_shelter_dag.retrieve_data manual__2023-11-21T00:02:40.015000+00:00 [queued]>
[2023-11-21T00:02:41.817+0000] {taskinstance.py:1361} INFO - Starting attempt 1 of 2
[2023-11-21T00:02:41.825+0000] {taskinstance.py:1382} INFO - Executing <Task(PythonOperator): retrieve_data> on 2023-11-21 00:02:40.015000+00:00
[2023-11-21T00:02:41.831+0000] {standard_task_runner.py:57} INFO - Started process 151 to run task
[2023-11-21T00:02:41.834+0000] {standard_task_runner.py:84} INFO - Running: ['***', 'tasks', 'run', 'austin_animal_shelter_dag', 'retrieve_data', 'manual__2023-11-21T00:02:40.015000+00:00', '--job-id', '148', '--raw', '--subdir', 'DAGS_FOLDER/DAG.py', '--cfg-path', '/tmp/tmpoxwxphqi']
[2023-11-21T00:02:41.837+0000] {standard_task_runner.py:85} INFO - Job 148: Subtask retrieve_data
[2023-11-21T00:02:41.879+0000] {task_command.py:416} INFO - Running <TaskInstance: austin_animal_shelter_dag.retrieve_data manual__2023-11-21T00:02:40.015000+00:00 [running]> on host 24c5dabd8600
[2023-11-21T00:02:41.932+0000] {taskinstance.py:1662} INFO - Exporting env vars: AIRFLOW_CTX_DAG_OWNER='***' AIRFLOW_CTX_DAG_ID='austin_animal_shelter_dag' AIRFLOW_CTX_TASK_ID='retrieve_data' AIRFLOW_CTX_EXECUTION_DATE='2023-11-21T00:02:40.015000+00:00' AIRFLOW_CTX_TRY_NUMBER='1' AIRFLOW_CTX_DAG_RUN_ID='manual__2023-11-21T00:02:40.015000+00:00'
[2023-11-21T00:02:42.430+0000] {taskinstance.py:1937} ERROR - Task failed with exception
Traceback (most recent call last):
  File "/home/airflow/.local/lib/python3.8/site-packages/airflow/operators/python.py", line 192, in execute
    return_value = self.execute_callable()
  File "/home/airflow/.local/lib/python3.8/site-packages/airflow/operators/python.py", line 209, in execute_callable
    return self.python_callable(*self.op_args, **self.op_kwargs)
  File "/opt/airflow/dags/Scripts/etl.py", line 60, in retrieve_data
    objects_to_delete = s3.list_objects_v2(Bucket=BUCKET_NAME, Prefix='raw_data/')
  File "/home/airflow/.local/lib/python3.8/site-packages/botocore/client.py", line 535, in _api_call
    return self._make_api_call(operation_name, kwargs)
  File "/home/airflow/.local/lib/python3.8/site-packages/botocore/client.py", line 980, in _make_api_call
    raise error_class(parsed_response, operation_name)
botocore.exceptions.ClientError: An error occurred (AccessDenied) when calling the ListObjectsV2 operation: Access Denied
[2023-11-21T00:02:42.446+0000] {taskinstance.py:1400} INFO - Marking task as UP_FOR_RETRY. dag_id=austin_animal_shelter_dag, task_id=retrieve_data, execution_date=20231121T000240, start_date=20231121T000241, end_date=20231121T000242
[2023-11-21T00:02:42.462+0000] {standard_task_runner.py:104} ERROR - Failed to execute job 148 for task retrieve_data (An error occurred (AccessDenied) when calling the ListObjectsV2 operation: Access Denied; 151)
[2023-11-21T00:02:42.513+0000] {local_task_job_runner.py:228} INFO - Task exited with return code 1
[2023-11-21T00:02:42.531+0000] {taskinstance.py:2778} INFO - 0 downstream tasks scheduled from follow-on schedule check
